{
  "comments": [
    {
      "key": {
        "uuid": "9a3d3df0_e4f04600",
        "filename": "config/utils/generate_config.py",
        "patchSetId": 1
      },
      "lineNbr": 60,
      "author": {
        "id": 2997
      },
      "writtenOn": "2017-12-20T19:39:34Z",
      "side": 1,
      "message": "this will break if the user stores the keys in any other place ...\nPlus, the \u0027except CalledProcessError\u0027 should have caught this. Could you share the trace for the failure without this patch?",
      "range": {
        "startLine": 60,
        "startChar": 0,
        "endLine": 60,
        "endChar": 59
      },
      "revId": "7b1a300d1c54096e1da403649b314ff65e65109e",
      "serverId": "bbac25d2-bf60-4904-9ba8-a72fc000d6c5",
      "unresolved": false
    }
  ]
}